{"uuid": "986f74c4-9673-4512-9982-421a96570d14", "children": ["571a5f11-ec69-4ad1-82b8-507aebd58bdc", "e4532dfd-805e-4204-97de-19215b801015", "a3de518a-175c-4df5-9cfc-6e6257b25ad5", "305d023a-dc2c-46dc-8104-6e7740684ff6"], "befores": [{"name": "base_fixture", "status": "passed", "start": 1631460167867, "stop": 1631460167882}], "afters": [{"name": "base_fixture::0", "status": "broken", "statusDetails": {"message": "urllib3.exceptions.MaxRetryError: HTTPConnectionPool(host='127.0.0.1', port=52651): Max retries exceeded with url: /session/fbb0da81-c760-4de5-88e7-705f9d2ec076/screenshot (Caused by NewConnectionError('<urllib3.connection.HTTPConnection object at 0x00000221F4096EE0>: Failed to establish a new connection: [WinError 10061] No connection could be made because the target machine actively refused it'))\n", "trace": "  File \"c:\\python\\python396\\lib\\site-packages\\allure_commons\\_allure.py\", line 200, in __call__\n    return self._fixture_function(*args, **kwargs)\n  File \"c:\\python\\python396\\lib\\site-packages\\_pytest\\fixtures.py\", line 941, in _teardown_yield_fixture\n    next(it)\n  File \"C:\\Users\\kumarmu\\Documents\\pythonSelenium\\HybridFramework\\conftest.py\", line 25, in base_fixture\n    gen.closeApp()\n  File \"C:\\Users\\kumarmu\\Documents\\pythonSelenium\\HybridFramework\\keywords\\genKeyword.py\", line 73, in closeApp\n    self.reportSuccess(\"Browser closed successfully\")\n  File \"C:\\Users\\kumarmu\\Documents\\pythonSelenium\\HybridFramework\\keywords\\genKeyword.py\", line 166, in reportSuccess\n    self.takeScreenshot()\n  File \"C:\\Users\\kumarmu\\Documents\\pythonSelenium\\HybridFramework\\keywords\\genKeyword.py\", line 156, in takeScreenshot\n    allure.attach(self.driver.get_screenshot_as_png(), \"Screenshot taken at : \"+str(datetime.now()), AttachmentType.PNG)\n  File \"c:\\python\\python396\\lib\\site-packages\\selenium\\webdriver\\remote\\webdriver.py\", line 1064, in get_screenshot_as_png\n    return base64.b64decode(self.get_screenshot_as_base64().encode('ascii'))\n  File \"c:\\python\\python396\\lib\\site-packages\\selenium\\webdriver\\remote\\webdriver.py\", line 1074, in get_screenshot_as_base64\n    return self.execute(Command.SCREENSHOT)['value']\n  File \"c:\\python\\python396\\lib\\site-packages\\selenium\\webdriver\\remote\\webdriver.py\", line 319, in execute\n    response = self.command_executor.execute(driver_command, params)\n  File \"c:\\python\\python396\\lib\\site-packages\\selenium\\webdriver\\remote\\remote_connection.py\", line 374, in execute\n    return self._request(command_info[0], url, body=data)\n  File \"c:\\python\\python396\\lib\\site-packages\\selenium\\webdriver\\remote\\remote_connection.py\", line 397, in _request\n    resp = self._conn.request(method, url, body=body, headers=headers)\n  File \"c:\\python\\python396\\lib\\site-packages\\urllib3\\request.py\", line 74, in request\n    return self.request_encode_url(\n  File \"c:\\python\\python396\\lib\\site-packages\\urllib3\\request.py\", line 96, in request_encode_url\n    return self.urlopen(method, url, **extra_kw)\n  File \"c:\\python\\python396\\lib\\site-packages\\urllib3\\poolmanager.py\", line 375, in urlopen\n    response = conn.urlopen(method, u.request_uri, **kw)\n  File \"c:\\python\\python396\\lib\\site-packages\\urllib3\\connectionpool.py\", line 783, in urlopen\n    return self.urlopen(\n  File \"c:\\python\\python396\\lib\\site-packages\\urllib3\\connectionpool.py\", line 783, in urlopen\n    return self.urlopen(\n  File \"c:\\python\\python396\\lib\\site-packages\\urllib3\\connectionpool.py\", line 783, in urlopen\n    return self.urlopen(\n  File \"c:\\python\\python396\\lib\\site-packages\\urllib3\\connectionpool.py\", line 755, in urlopen\n    retries = retries.increment(\n  File \"c:\\python\\python396\\lib\\site-packages\\urllib3\\util\\retry.py\", line 574, in increment\n    raise MaxRetryError(_pool, url, error or ResponseError(cause))\n"}, "steps": [{"name": "Closing browser", "status": "broken", "statusDetails": {"message": "urllib3.exceptions.MaxRetryError: HTTPConnectionPool(host='127.0.0.1', port=52651): Max retries exceeded with url: /session/fbb0da81-c760-4de5-88e7-705f9d2ec076/screenshot (Caused by NewConnectionError('<urllib3.connection.HTTPConnection object at 0x00000221F4096EE0>: Failed to establish a new connection: [WinError 10061] No connection could be made because the target machine actively refused it'))\n", "trace": "  File \"C:\\Users\\kumarmu\\Documents\\pythonSelenium\\HybridFramework\\keywords\\genKeyword.py\", line 73, in closeApp\n    self.reportSuccess(\"Browser closed successfully\")\n  File \"C:\\Users\\kumarmu\\Documents\\pythonSelenium\\HybridFramework\\keywords\\genKeyword.py\", line 166, in reportSuccess\n    self.takeScreenshot()\n  File \"C:\\Users\\kumarmu\\Documents\\pythonSelenium\\HybridFramework\\keywords\\genKeyword.py\", line 156, in takeScreenshot\n    allure.attach(self.driver.get_screenshot_as_png(), \"Screenshot taken at : \"+str(datetime.now()), AttachmentType.PNG)\n  File \"c:\\python\\python396\\lib\\site-packages\\selenium\\webdriver\\remote\\webdriver.py\", line 1064, in get_screenshot_as_png\n    return base64.b64decode(self.get_screenshot_as_base64().encode('ascii'))\n  File \"c:\\python\\python396\\lib\\site-packages\\selenium\\webdriver\\remote\\webdriver.py\", line 1074, in get_screenshot_as_base64\n    return self.execute(Command.SCREENSHOT)['value']\n  File \"c:\\python\\python396\\lib\\site-packages\\selenium\\webdriver\\remote\\webdriver.py\", line 319, in execute\n    response = self.command_executor.execute(driver_command, params)\n  File \"c:\\python\\python396\\lib\\site-packages\\selenium\\webdriver\\remote\\remote_connection.py\", line 374, in execute\n    return self._request(command_info[0], url, body=data)\n  File \"c:\\python\\python396\\lib\\site-packages\\selenium\\webdriver\\remote\\remote_connection.py\", line 397, in _request\n    resp = self._conn.request(method, url, body=body, headers=headers)\n  File \"c:\\python\\python396\\lib\\site-packages\\urllib3\\request.py\", line 74, in request\n    return self.request_encode_url(\n  File \"c:\\python\\python396\\lib\\site-packages\\urllib3\\request.py\", line 96, in request_encode_url\n    return self.urlopen(method, url, **extra_kw)\n  File \"c:\\python\\python396\\lib\\site-packages\\urllib3\\poolmanager.py\", line 375, in urlopen\n    response = conn.urlopen(method, u.request_uri, **kw)\n  File \"c:\\python\\python396\\lib\\site-packages\\urllib3\\connectionpool.py\", line 783, in urlopen\n    return self.urlopen(\n  File \"c:\\python\\python396\\lib\\site-packages\\urllib3\\connectionpool.py\", line 783, in urlopen\n    return self.urlopen(\n  File \"c:\\python\\python396\\lib\\site-packages\\urllib3\\connectionpool.py\", line 783, in urlopen\n    return self.urlopen(\n  File \"c:\\python\\python396\\lib\\site-packages\\urllib3\\connectionpool.py\", line 755, in urlopen\n    retries = retries.increment(\n  File \"c:\\python\\python396\\lib\\site-packages\\urllib3\\util\\retry.py\", line 574, in increment\n    raise MaxRetryError(_pool, url, error or ResponseError(cause))\n"}, "start": 1631460212318, "stop": 1631460228509}], "start": 1631460202304, "stop": 1631460228604}], "start": 1631460167867, "stop": 1631460228604}